/home/kumarv/willa099/miniconda3/envs/pytorch4/lib/python3.6/site-packages/pyarrow/pandas_compat.py:742: FutureWarning: .labels was deprecated in version 0.24.0. Use .codes instead.
  labels, = index.labels
Traceback (most recent call last):
  File "grid_search_rf.py", line 64, in <module>
    lake_df = pd.read_csv("../../metadata/diff/target_"+target_id+"_wStats_wSeason_wPercDiffDepth.csv")
  File "/home/kumarv/willa099/miniconda3/envs/pytorch4/lib/python3.6/site-packages/pandas/io/parsers.py", line 685, in parser_f
    return _read(filepath_or_buffer, kwds)
  File "/home/kumarv/willa099/miniconda3/envs/pytorch4/lib/python3.6/site-packages/pandas/io/parsers.py", line 463, in _read
    data = parser.read(nrows)
  File "/home/kumarv/willa099/miniconda3/envs/pytorch4/lib/python3.6/site-packages/pandas/io/parsers.py", line 1154, in read
    ret = self._engine.read(nrows)
  File "/home/kumarv/willa099/miniconda3/envs/pytorch4/lib/python3.6/site-packages/pandas/io/parsers.py", line 2059, in read
    data = self._reader.read(nrows)
  File "pandas/_libs/parsers.pyx", line 881, in pandas._libs.parsers.TextReader.read
  File "pandas/_libs/parsers.pyx", line 896, in pandas._libs.parsers.TextReader._read_low_memory
  File "pandas/_libs/parsers.pyx", line 973, in pandas._libs.parsers.TextReader._read_rows
  File "pandas/_libs/parsers.pyx", line 1105, in pandas._libs.parsers.TextReader._convert_column_data
  File "pandas/_libs/parsers.pyx", line 1151, in pandas._libs.parsers.TextReader._convert_tokens
  File "pandas/_libs/parsers.pyx", line 1197, in pandas._libs.parsers.TextReader._convert_with_dtype
  File "/home/kumarv/willa099/miniconda3/envs/pytorch4/lib/python3.6/site-packages/pandas/core/dtypes/common.py", line 678, in is_categorical_dtype
    def is_categorical_dtype(arr_or_dtype):
KeyboardInterrupt
/home/kumarv/willa099/miniconda3/envs/pytorch4/lib/python3.6/site-packages/pyarrow/pandas_compat.py:742: FutureWarning: .labels was deprecated in version 0.24.0. Use .codes instead.
  labels, = index.labels
Exception ignored in: <Finalize object, dead>
Traceback (most recent call last):
  File "/home/kumarv/willa099/miniconda3/envs/pytorch4/lib/python3.6/multiprocessing/util.py", line 186, in __call__
    res = self._callback(*self._args, **self._kwargs)
  File "/home/kumarv/willa099/miniconda3/envs/pytorch4/lib/python3.6/site-packages/sklearn/externals/joblib/externals/loky/backend/synchronize.py", line 96, in _cleanup
    sem_unlink(name)
FileNotFoundError: [Errno 2] No such file or directory
Exception ignored in: <Finalize object, dead>
Traceback (most recent call last):
  File "/home/kumarv/willa099/miniconda3/envs/pytorch4/lib/python3.6/multiprocessing/util.py", line 186, in __call__
    res = self._callback(*self._args, **self._kwargs)
  File "/home/kumarv/willa099/miniconda3/envs/pytorch4/lib/python3.6/site-packages/sklearn/externals/joblib/externals/loky/backend/synchronize.py", line 96, in _cleanup
    sem_unlink(name)
FileNotFoundError: [Errno 2] No such file or directory
Exception ignored in: <Finalize object, dead>
Traceback (most recent call last):
  File "/home/kumarv/willa099/miniconda3/envs/pytorch4/lib/python3.6/multiprocessing/util.py", line 186, in __call__
    res = self._callback(*self._args, **self._kwargs)
  File "/home/kumarv/willa099/miniconda3/envs/pytorch4/lib/python3.6/site-packages/sklearn/externals/joblib/externals/loky/backend/synchronize.py", line 96, in _cleanup
    sem_unlink(name)
FileNotFoundError: [Errno 2] No such file or directory
Exception ignored in: <Finalize object, dead>
Traceback (most recent call last):
  File "/home/kumarv/willa099/miniconda3/envs/pytorch4/lib/python3.6/multiprocessing/util.py", line 186, in __call__
    res = self._callback(*self._args, **self._kwargs)
  File "/home/kumarv/willa099/miniconda3/envs/pytorch4/lib/python3.6/site-packages/sklearn/externals/joblib/externals/loky/backend/synchronize.py", line 96, in _cleanup
    sem_unlink(name)
FileNotFoundError: [Errno 2] No such file or directory
Exception ignored in: <Finalize object, dead>
Traceback (most recent call last):
  File "/home/kumarv/willa099/miniconda3/envs/pytorch4/lib/python3.6/multiprocessing/util.py", line 186, in __call__
    res = self._callback(*self._args, **self._kwargs)
  File "/home/kumarv/willa099/miniconda3/envs/pytorch4/lib/python3.6/site-packages/sklearn/externals/joblib/externals/loky/backend/synchronize.py", line 96, in _cleanup
    sem_unlink(name)
FileNotFoundError: [Errno 2] No such file or directory
Exception ignored in: <Finalize object, dead>
Traceback (most recent call last):
  File "/home/kumarv/willa099/miniconda3/envs/pytorch4/lib/python3.6/multiprocessing/util.py", line 186, in __call__
    res = self._callback(*self._args, **self._kwargs)
  File "/home/kumarv/willa099/miniconda3/envs/pytorch4/lib/python3.6/site-packages/sklearn/externals/joblib/externals/loky/backend/synchronize.py", line 96, in _cleanup
    sem_unlink(name)
FileNotFoundError: [Errno 2] No such file or directory
Exception ignored in: <Finalize object, dead>
Traceback (most recent call last):
  File "/home/kumarv/willa099/miniconda3/envs/pytorch4/lib/python3.6/multiprocessing/util.py", line 186, in __call__
    res = self._callback(*self._args, **self._kwargs)
  File "/home/kumarv/willa099/miniconda3/envs/pytorch4/lib/python3.6/site-packages/sklearn/externals/joblib/externals/loky/backend/synchronize.py", line 96, in _cleanup
    sem_unlink(name)
FileNotFoundError: [Errno 2] No such file or directory
Exception ignored in: <Finalize object, dead>
Traceback (most recent call last):
  File "/home/kumarv/willa099/miniconda3/envs/pytorch4/lib/python3.6/multiprocessing/util.py", line 186, in __call__
    res = self._callback(*self._args, **self._kwargs)
  File "/home/kumarv/willa099/miniconda3/envs/pytorch4/lib/python3.6/site-packages/sklearn/externals/joblib/externals/loky/backend/synchronize.py", line 96, in _cleanup
    sem_unlink(name)
FileNotFoundError: [Errno 2] No such file or directory
Exception ignored in: <Finalize object, dead>
Traceback (most recent call last):
  File "/home/kumarv/willa099/miniconda3/envs/pytorch4/lib/python3.6/multiprocessing/util.py", line 186, in __call__
    res = self._callback(*self._args, **self._kwargs)
  File "/home/kumarv/willa099/miniconda3/envs/pytorch4/lib/python3.6/site-packages/sklearn/externals/joblib/externals/loky/backend/synchronize.py", line 96, in _cleanup
    sem_unlink(name)
FileNotFoundError: [Errno 2] No such file or directory
Exception ignored in: <Finalize object, dead>
Traceback (most recent call last):
  File "/home/kumarv/willa099/miniconda3/envs/pytorch4/lib/python3.6/multiprocessing/util.py", line 186, in __call__
    res = self._callback(*self._args, **self._kwargs)
  File "/home/kumarv/willa099/miniconda3/envs/pytorch4/lib/python3.6/site-packages/sklearn/externals/joblib/externals/loky/backend/synchronize.py", line 96, in _cleanup
    sem_unlink(name)
FileNotFoundError: [Errno 2] No such file or directory
Exception ignored in: <Finalize object, dead>
Traceback (most recent call last):
  File "/home/kumarv/willa099/miniconda3/envs/pytorch4/lib/python3.6/multiprocessing/util.py", line 186, in __call__
    res = self._callback(*self._args, **self._kwargs)
  File "/home/kumarv/willa099/miniconda3/envs/pytorch4/lib/python3.6/site-packages/sklearn/externals/joblib/externals/loky/backend/synchronize.py", line 96, in _cleanup
    sem_unlink(name)
FileNotFoundError: [Errno 2] No such file or directory
Exception ignored in: <Finalize object, dead>
Traceback (most recent call last):
  File "/home/kumarv/willa099/miniconda3/envs/pytorch4/lib/python3.6/multiprocessing/util.py", line 186, in __call__
    res = self._callback(*self._args, **self._kwargs)
  File "/home/kumarv/willa099/miniconda3/envs/pytorch4/lib/python3.6/site-packages/sklearn/externals/joblib/externals/loky/backend/synchronize.py", line 96, in _cleanup
    sem_unlink(name)
FileNotFoundError: [Errno 2] No such file or directory
Exception ignored in: <Finalize object, dead>
Traceback (most recent call last):
  File "/home/kumarv/willa099/miniconda3/envs/pytorch4/lib/python3.6/multiprocessing/util.py", line 186, in __call__
    res = self._callback(*self._args, **self._kwargs)
  File "/home/kumarv/willa099/miniconda3/envs/pytorch4/lib/python3.6/site-packages/sklearn/externals/joblib/externals/loky/backend/synchronize.py", line 96, in _cleanup
    sem_unlink(name)
FileNotFoundError: [Errno 2] No such file or directory
Exception ignored in: <Finalize object, dead>
Traceback (most recent call last):
  File "/home/kumarv/willa099/miniconda3/envs/pytorch4/lib/python3.6/multiprocessing/util.py", line 186, in __call__
    res = self._callback(*self._args, **self._kwargs)
  File "/home/kumarv/willa099/miniconda3/envs/pytorch4/lib/python3.6/site-packages/sklearn/externals/joblib/externals/loky/backend/synchronize.py", line 96, in _cleanup
    sem_unlink(name)
FileNotFoundError: [Errno 2] No such file or directory
Exception ignored in: <Finalize object, dead>
Traceback (most recent call last):
  File "/home/kumarv/willa099/miniconda3/envs/pytorch4/lib/python3.6/multiprocessing/util.py", line 186, in __call__
    res = self._callback(*self._args, **self._kwargs)
  File "/home/kumarv/willa099/miniconda3/envs/pytorch4/lib/python3.6/site-packages/sklearn/externals/joblib/externals/loky/backend/synchronize.py", line 96, in _cleanup
    sem_unlink(name)
FileNotFoundError: [Errno 2] No such file or directory
Exception ignored in: <Finalize object, dead>
Traceback (most recent call last):
  File "/home/kumarv/willa099/miniconda3/envs/pytorch4/lib/python3.6/multiprocessing/util.py", line 186, in __call__
    res = self._callback(*self._args, **self._kwargs)
  File "/home/kumarv/willa099/miniconda3/envs/pytorch4/lib/python3.6/site-packages/sklearn/externals/joblib/externals/loky/backend/synchronize.py", line 96, in _cleanup
    sem_unlink(name)
FileNotFoundError: [Errno 2] No such file or directory
Exception ignored in: <Finalize object, dead>
Traceback (most recent call last):
  File "/home/kumarv/willa099/miniconda3/envs/pytorch4/lib/python3.6/multiprocessing/util.py", line 186, in __call__
    res = self._callback(*self._args, **self._kwargs)
  File "/home/kumarv/willa099/miniconda3/envs/pytorch4/lib/python3.6/site-packages/sklearn/externals/joblib/externals/loky/backend/synchronize.py", line 96, in _cleanup
    sem_unlink(name)
FileNotFoundError: [Errno 2] No such file or directory
Exception ignored in: <Finalize object, dead>
Traceback (most recent call last):
  File "/home/kumarv/willa099/miniconda3/envs/pytorch4/lib/python3.6/multiprocessing/util.py", line 186, in __call__
    res = self._callback(*self._args, **self._kwargs)
  File "/home/kumarv/willa099/miniconda3/envs/pytorch4/lib/python3.6/site-packages/sklearn/externals/joblib/externals/loky/backend/synchronize.py", line 96, in _cleanup
    sem_unlink(name)
FileNotFoundError: [Errno 2] No such file or directory
Exception ignored in: <Finalize object, dead>
Traceback (most recent call last):
  File "/home/kumarv/willa099/miniconda3/envs/pytorch4/lib/python3.6/multiprocessing/util.py", line 186, in __call__
    res = self._callback(*self._args, **self._kwargs)
  File "/home/kumarv/willa099/miniconda3/envs/pytorch4/lib/python3.6/site-packages/sklearn/externals/joblib/externals/loky/backend/synchronize.py", line 96, in _cleanup
    sem_unlink(name)
FileNotFoundError: [Errno 2] No such file or directory
Exception ignored in: <Finalize object, dead>
Traceback (most recent call last):
  File "/home/kumarv/willa099/miniconda3/envs/pytorch4/lib/python3.6/multiprocessing/util.py", line 186, in __call__
    res = self._callback(*self._args, **self._kwargs)
  File "/home/kumarv/willa099/miniconda3/envs/pytorch4/lib/python3.6/site-packages/sklearn/externals/joblib/externals/loky/backend/synchronize.py", line 96, in _cleanup
    sem_unlink(name)
FileNotFoundError: [Errno 2] No such file or directory
Exception ignored in: <Finalize object, dead>
Traceback (most recent call last):
  File "/home/kumarv/willa099/miniconda3/envs/pytorch4/lib/python3.6/multiprocessing/util.py", line 186, in __call__
    res = self._callback(*self._args, **self._kwargs)
  File "/home/kumarv/willa099/miniconda3/envs/pytorch4/lib/python3.6/site-packages/sklearn/externals/joblib/externals/loky/backend/synchronize.py", line 96, in _cleanup
    sem_unlink(name)
FileNotFoundError: [Errno 2] No such file or directory
Exception ignored in: <Finalize object, dead>
Traceback (most recent call last):
  File "/home/kumarv/willa099/miniconda3/envs/pytorch4/lib/python3.6/multiprocessing/util.py", line 186, in __call__
    res = self._callback(*self._args, **self._kwargs)
  File "/home/kumarv/willa099/miniconda3/envs/pytorch4/lib/python3.6/site-packages/sklearn/externals/joblib/externals/loky/backend/synchronize.py", line 96, in _cleanup
    sem_unlink(name)
FileNotFoundError: [Errno 2] No such file or directory
Exception ignored in: <Finalize object, dead>
Traceback (most recent call last):
  File "/home/kumarv/willa099/miniconda3/envs/pytorch4/lib/python3.6/multiprocessing/util.py", line 186, in __call__
    res = self._callback(*self._args, **self._kwargs)
  File "/home/kumarv/willa099/miniconda3/envs/pytorch4/lib/python3.6/site-packages/sklearn/externals/joblib/externals/loky/backend/synchronize.py", line 96, in _cleanup
    sem_unlink(name)
FileNotFoundError: [Errno 2] No such file or directory
Exception ignored in: <Finalize object, dead>
Traceback (most recent call last):
  File "/home/kumarv/willa099/miniconda3/envs/pytorch4/lib/python3.6/multiprocessing/util.py", line 186, in __call__
    res = self._callback(*self._args, **self._kwargs)
  File "/home/kumarv/willa099/miniconda3/envs/pytorch4/lib/python3.6/site-packages/sklearn/externals/joblib/externals/loky/backend/synchronize.py", line 96, in _cleanup
    sem_unlink(name)
FileNotFoundError: [Errno 2] No such file or directory
Exception ignored in: <Finalize object, dead>
Traceback (most recent call last):
  File "/home/kumarv/willa099/miniconda3/envs/pytorch4/lib/python3.6/multiprocessing/util.py", line 186, in __call__
    res = self._callback(*self._args, **self._kwargs)
  File "/home/kumarv/willa099/miniconda3/envs/pytorch4/lib/python3.6/site-packages/sklearn/externals/joblib/externals/loky/backend/synchronize.py", line 96, in _cleanup
    sem_unlink(name)
FileNotFoundError: [Errno 2] No such file or directory
Exception ignored in: <Finalize object, dead>
Traceback (most recent call last):
  File "/home/kumarv/willa099/miniconda3/envs/pytorch4/lib/python3.6/multiprocessing/util.py", line 186, in __call__
    res = self._callback(*self._args, **self._kwargs)
  File "/home/kumarv/willa099/miniconda3/envs/pytorch4/lib/python3.6/site-packages/sklearn/externals/joblib/externals/loky/backend/synchronize.py", line 96, in _cleanup
    sem_unlink(name)
FileNotFoundError: [Errno 2] No such file or directory
Exception ignored in: <Finalize object, dead>
Traceback (most recent call last):
  File "/home/kumarv/willa099/miniconda3/envs/pytorch4/lib/python3.6/multiprocessing/util.py", line 186, in __call__
    res = self._callback(*self._args, **self._kwargs)
  File "/home/kumarv/willa099/miniconda3/envs/pytorch4/lib/python3.6/site-packages/sklearn/externals/joblib/externals/loky/backend/synchronize.py", line 96, in _cleanup
    sem_unlink(name)
FileNotFoundError: [Errno 2] No such file or directory
ExcZeption ignored in: <Finalize object, dead>
Traceback (most recent call last):
  File "/home/kumarv/willa099/miniconda3/envs/pytorch4/lib/python3.6/multiprocessing/util.py", line 186, in __call__
    res = self._callback(*self._args, **self._kwargs)
  File "/home/kumarv/willa099/miniconda3/envs/pytorch4/lib/python3.6/site-packages/sklearn/externals/joblib/externals/loky/backend/synchronize.py", line 96, in _cleanup
    sem_unlink(name)
FileNotFoundError: [Errno 2] No such file or directory
BEST SCORE:  0.5477258929307649
{'n_estimators': 4250}
Traceback (most recent call last):
  File "/home/kumarv/willa099/miniconda3/envs/pytorch4/lib/python3.6/multiprocessing/util.py", line 262, in _run_finalizers
    finalizer()
  File "/home/kumarv/willa099/miniconda3/envs/pytorch4/lib/python3.6/multiprocessing/util.py", line 186, in __call__
    res = self._callback(*self._args, **self._kwargs)
  File "/home/kumarv/willa099/miniconda3/envs/pytorch4/lib/python3.6/site-packages/sklearn/externals/joblib/externals/loky/backend/synchronize.py", line 96, in _cleanup
    sem_unlink(name)
FileNotFoundError: [Errno 2] No such file or directory
Traceback (most recent call last):
  File "/home/kumarv/willa099/miniconda3/envs/pytorch4/lib/python3.6/multiprocessing/util.py", line 262, in _run_finalizers
    finalizer()
  File "/home/kumarv/willa099/miniconda3/envs/pytorch4/lib/python3.6/multiprocessing/util.py", line 186, in __call__
    res = self._callback(*self._args, **self._kwargs)
  File "/home/kumarv/willa099/miniconda3/envs/pytorch4/lib/python3.6/site-packages/sklearn/externals/joblib/externals/loky/backend/synchronize.py", line 96, in _cleanup
    sem_unlink(name)
FileNotFoundError: [Errno 2] No such file or directory
Traceback (most recent call last):
  File "/home/kumarv/willa099/miniconda3/envs/pytorch4/lib/python3.6/multiprocessing/util.py", line 262, in _run_finalizers
    finalizer()
  File "/home/kumarv/willa099/miniconda3/envs/pytorch4/lib/python3.6/multiprocessing/util.py", line 186, in __call__
    res = self._callback(*self._args, **self._kwargs)
  File "/home/kumarv/willa099/miniconda3/envs/pytorch4/lib/python3.6/site-packages/sklearn/externals/joblib/externals/loky/backend/synchronize.py", line 96, in _cleanup
    sem_unlink(name)
FileNotFoundError: [Errno 2] No such file or directory
Traceback (most recent call last):
  File "/home/kumarv/willa099/miniconda3/envs/pytorch4/lib/python3.6/multiprocessing/util.py", line 262, in _run_finalizers
    finalizer()
  File "/home/kumarv/willa099/miniconda3/envs/pytorch4/lib/python3.6/multiprocessing/util.py", line 186, in __call__
    res = self._callback(*self._args, **self._kwargs)
  File "/home/kumarv/willa099/miniconda3/envs/pytorch4/lib/python3.6/site-packages/sklearn/externals/joblib/externals/loky/backend/synchronize.py", line 96, in _cleanup
    sem_unlink(name)
FileNotFoundError: [Errno 2] No such file or directory
Traceback (most recent call last):
  File "/home/kumarv/willa099/miniconda3/envs/pytorch4/lib/python3.6/multiprocessing/util.py", line 262, in _run_finalizers
    finalizer()
  File "/home/kumarv/willa099/miniconda3/envs/pytorch4/lib/python3.6/multiprocessing/util.py", line 186, in __call__
    res = self._callback(*self._args, **self._kwargs)
  File "/home/kumarv/willa099/miniconda3/envs/pytorch4/lib/python3.6/site-packages/sklearn/externals/joblib/externals/loky/backend/synchronize.py", line 96, in _cleanup
    sem_unlink(name)
FileNotFoundError: [Errno 2] No such file or directory
Traceback (most recent call last):
  File "/home/kumarv/willa099/miniconda3/envs/pytorch4/lib/python3.6/multiprocessing/util.py", line 262, in _run_finalizers
    finalizer()
  File "/home/kumarv/willa099/miniconda3/envs/pytorch4/lib/python3.6/multiprocessing/util.py", line 186, in __call__
    res = self._callback(*self._args, **self._kwargs)
  File "/home/kumarv/willa099/miniconda3/envs/pytorch4/lib/python3.6/site-packages/sklearn/externals/joblib/externals/loky/backend/synchronize.py", line 96, in _cleanup
    sem_unlink(name)
FileNotFoundError: [Errno 2] No such file or directory
/home/kumarv/willa099/miniconda3/envs/pytorch4/lib/python3.6/site-packages/sklearn/externals/joblib/externals/loky/backend/semaphore_tracker.py:198: UserWarning: semaphore_tracker: There appear to be 34 leaked semaphores to clean up at shutdown
  len(cache))
/home/kumarv/willa099/miniconda3/envs/pytorch4/lib/python3.6/site-packages/sklearn/externals/joblib/externals/loky/backend/semaphore_tracker.py:213: UserWarning: semaphore_tracker: '/loky-20360-q0582sjf': FileNotFoundError(2, 'No such file or directory')
  warnings.warn('semaphore_tracker: %r: %r' % (name, e))
/home/kumarv/willa099/miniconda3/envs/pytorch4/lib/python3.6/site-packages/sklearn/externals/joblib/externals/loky/backend/semaphore_tracker.py:213: UserWarning: semaphore_tracker: '/loky-20360-gyoatpcn': FileNotFoundError(2, 'No such file or directory')
  warnings.warn('semaphore_tracker: %r: %r' % (name, e))
/home/kumarv/willa099/miniconda3/envs/pytorch4/lib/python3.6/site-packages/sklearn/externals/joblib/externals/loky/backend/semaphore_tracker.py:213: UserWarning: semaphore_tracker: '/loky-20360-ymx23q99': FileNotFoundError(2, 'No such file or directory')
  warnings.warn('semaphore_tracker: %r: %r' % (name, e))
/home/kumarv/willa099/miniconda3/envs/pytorch4/lib/python3.6/site-packages/sklearn/externals/joblib/externals/loky/backend/semaphore_tracker.py:213: UserWarning: semaphore_tracker: '/loky-20360-hk6hvldo': FileNotFoundError(2, 'No such file or directory')
  warnings.warn('semaphore_tracker: %r: %r' % (name, e))
/home/kumarv/willa099/miniconda3/envs/pytorch4/lib/python3.6/site-packages/sklearn/externals/joblib/externals/loky/backend/semaphore_tracker.py:213: UserWarning: semaphore_tracker: '/loky-20360-kbsilqye': FileNotFoundError(2, 'No such file or directory')
  warnings.warn('semaphore_tracker: %r: %r' % (name, e))
/home/kumarv/willa099/miniconda3/envs/pytorch4/lib/python3.6/site-packages/sklearn/externals/joblib/externals/loky/backend/semaphore_tracker.py:213: UserWarning: semaphore_tracker: '/loky-20360-gm36jv37': FileNotFoundError(2, 'No such file or directory')
  warnings.warn('semaphore_tracker: %r: %r' % (name, e))
/home/kumarv/willa099/miniconda3/envs/pytorch4/lib/python3.6/site-packages/sklearn/externals/joblib/externals/loky/backend/semaphore_tracker.py:213: UserWarning: semaphore_tracker: '/loky-20360-ryhwleeg': FileNotFoundError(2, 'No such file or directory')
  warnings.warn('semaphore_tracker: %r: %r' % (name, e))
/home/kumarv/willa099/miniconda3/envs/pytorch4/lib/python3.6/site-packages/sklearn/externals/joblib/externals/loky/backend/semaphore_tracker.py:213: UserWarning: semaphore_tracker: '/loky-20360-iluvy7xq': FileNotFoundError(2, 'No such file or directory')
  warnings.warn('semaphore_tracker: %r: %r' % (name, e))
/home/kumarv/willa099/miniconda3/envs/pytorch4/lib/python3.6/site-packages/sklearn/externals/joblib/externals/loky/backend/semaphore_tracker.py:213: UserWarning: semaphore_tracker: '/loky-20360-fuwbvuey': FileNotFoundError(2, 'No such file or directory')
  warnings.warn('semaphore_tracker: %r: %r' % (name, e))
/home/kumarv/willa099/miniconda3/envs/pytorch4/lib/python3.6/site-packages/sklearn/externals/joblib/externals/loky/backend/semaphore_tracker.py:213: UserWarning: semaphore_tracker: '/loky-20360-rm5z6ocy': FileNotFoundError(2, 'No such file or directory')
  warnings.warn('semaphore_tracker: %r: %r' % (name, e))
/home/kumarv/willa099/miniconda3/envs/pytorch4/lib/python3.6/site-packages/sklearn/externals/joblib/externals/loky/backend/semaphore_tracker.py:213: UserWarning: semaphore_tracker: '/loky-20360-0ynyfdjd': FileNotFoundError(2, 'No such file or directory')
  warnings.warn('semaphore_tracker: %r: %r' % (name, e))
/home/kumarv/willa099/miniconda3/envs/pytorch4/lib/python3.6/site-packages/sklearn/externals/joblib/externals/loky/backend/semaphore_tracker.py:213: UserWarning: semaphore_tracker: '/loky-20360-8xynn_r6': FileNotFoundError(2, 'No such file or directory')
  warnings.warn('semaphore_tracker: %r: %r' % (name, e))
/home/kumarv/willa099/miniconda3/envs/pytorch4/lib/python3.6/site-packages/sklearn/externals/joblib/externals/loky/backend/semaphore_tracker.py:213: UserWarning: semaphore_tracker: '/loky-20360-3nx5cmhg': FileNotFoundError(2, 'No such file or directory')
  warnings.warn('semaphore_tracker: %r: %r' % (name, e))
/home/kumarv/willa099/miniconda3/envs/pytorch4/lib/python3.6/site-packages/sklearn/externals/joblib/externals/loky/backend/semaphore_tracker.py:213: UserWarning: semaphore_tracker: '/loky-20360-1v5pj_ag': FileNotFoundError(2, 'No such file or directory')
  warnings.warn('semaphore_tracker: %r: %r' % (name, e))
/home/kumarv/willa099/miniconda3/envs/pytorch4/lib/python3.6/site-packages/sklearn/externals/joblib/externals/loky/backend/semaphore_tracker.py:213: UserWarning: semaphore_tracker: '/loky-20360-6r5tr422': FileNotFoundError(2, 'No such file or directory')
  warnings.warn('semaphore_tracker: %r: %r' % (name, e))
/home/kumarv/willa099/miniconda3/envs/pytorch4/lib/python3.6/site-packages/sklearn/externals/joblib/externals/loky/backend/semaphore_tracker.py:213: UserWarning: semaphore_tracker: '/loky-20360-55pi335i': FileNotFoundError(2, 'No such file or directory')
  warnings.warn('semaphore_tracker: %r: %r' % (name, e))
/home/kumarv/willa099/miniconda3/envs/pytorch4/lib/python3.6/site-packages/sklearn/externals/joblib/externals/loky/backend/semaphore_tracker.py:213: UserWarning: semaphore_tracker: '/loky-20360-jvqy5wbi': FileNotFoundError(2, 'No such file or directory')
  warnings.warn('semaphore_tracker: %r: %r' % (name, e))
/home/kumarv/willa099/miniconda3/envs/pytorch4/lib/python3.6/site-packages/sklearn/externals/joblib/externals/loky/backend/semaphore_tracker.py:213: UserWarning: semaphore_tracker: '/loky-20360-i8938jve': FileNotFoundError(2, 'No such file or directory')
  warnings.warn('semaphore_tracker: %r: %r' % (name, e))
/home/kumarv/willa099/miniconda3/envs/pytorch4/lib/python3.6/site-packages/sklearn/externals/joblib/externals/loky/backend/semaphore_tracker.py:213: UserWarning: semaphore_tracker: '/loky-20360-jj59iomo': FileNotFoundError(2, 'No such file or directory')
  warnings.warn('semaphore_tracker: %r: %r' % (name, e))
/home/kumarv/willa099/miniconda3/envs/pytorch4/lib/python3.6/site-packages/sklearn/externals/joblib/externals/loky/backend/semaphore_tracker.py:213: UserWarning: semaphore_tracker: '/loky-20360-e224uxzf': FileNotFoundError(2, 'No such file or directory')
  warnings.warn('semaphore_tracker: %r: %r' % (name, e))
/home/kumarv/willa099/miniconda3/envs/pytorch4/lib/python3.6/site-packages/sklearn/externals/joblib/externals/loky/backend/semaphore_tracker.py:213: UserWarning: semaphore_tracker: '/loky-20360-1im1s5co': FileNotFoundError(2, 'No such file or directory')
  warnings.warn('semaphore_tracker: %r: %r' % (name, e))
/home/kumarv/willa099/miniconda3/envs/pytorch4/lib/python3.6/site-packages/sklearn/externals/joblib/externals/loky/backend/semaphore_tracker.py:213: UserWarning: semaphore_tracker: '/loky-20360-mcscqgo1': FileNotFoundError(2, 'No such file or directory')
  warnings.warn('semaphore_tracker: %r: %r' % (name, e))
/home/kumarv/willa099/miniconda3/envs/pytorch4/lib/python3.6/site-packages/sklearn/externals/joblib/externals/loky/backend/semaphore_tracker.py:213: UserWarning: semaphore_tracker: '/loky-20360-z5y94c0k': FileNotFoundError(2, 'No such file or directory')
  warnings.warn('semaphore_tracker: %r: %r' % (name, e))
/home/kumarv/willa099/miniconda3/envs/pytorch4/lib/python3.6/site-packages/sklearn/externals/joblib/externals/loky/backend/semaphore_tracker.py:213: UserWarning: semaphore_tracker: '/loky-20360-8x5mougc': FileNotFoundError(2, 'No such file or directory')
  warnings.warn('semaphore_tracker: %r: %r' % (name, e))
/home/kumarv/willa099/miniconda3/envs/pytorch4/lib/python3.6/site-packages/sklearn/externals/joblib/externals/loky/backend/semaphore_tracker.py:213: UserWarning: semaphore_tracker: '/loky-20360-oj2tr1pg': FileNotFoundError(2, 'No such file or directory')
  warnings.warn('semaphore_tracker: %r: %r' % (name, e))
/home/kumarv/willa099/miniconda3/envs/pytorch4/lib/python3.6/site-packages/sklearn/externals/joblib/externals/loky/backend/semaphore_tracker.py:213: UserWarning: semaphore_tracker: '/loky-20360-jr53c0pr': FileNotFoundError(2, 'No such file or directory')
  warnings.warn('semaphore_tracker: %r: %r' % (name, e))
/home/kumarv/willa099/miniconda3/envs/pytorch4/lib/python3.6/site-packages/sklearn/externals/joblib/externals/loky/backend/semaphore_tracker.py:213: UserWarning: semaphore_tracker: '/loky-20360-0udm8k06': FileNotFoundError(2, 'No such file or directory')
  warnings.warn('semaphore_tracker: %r: %r' % (name, e))
/home/kumarv/willa099/miniconda3/envs/pytorch4/lib/python3.6/site-packages/sklearn/externals/joblib/externals/loky/backend/semaphore_tracker.py:213: UserWarning: semaphore_tracker: '/loky-20360-79mi6uyd': FileNotFoundError(2, 'No such file or directory')
  warnings.warn('semaphore_tracker: %r: %r' % (name, e))
/home/kumarv/willa099/miniconda3/envs/pytorch4/lib/python3.6/site-packages/sklearn/externals/joblib/externals/loky/backend/semaphore_tracker.py:213: UserWarning: semaphore_tracker: '/loky-20360-w0dtb_a6': FileNotFoundError(2, 'No such file or directory')
  warnings.warn('semaphore_tracker: %r: %r' % (name, e))
/home/kumarv/willa099/miniconda3/envs/pytorch4/lib/python3.6/site-packages/sklearn/externals/joblib/externals/loky/backend/semaphore_tracker.py:213: UserWarning: semaphore_tracker: '/loky-20360-7smjejki': FileNotFoundError(2, 'No such file or directory')
  warnings.warn('semaphore_tracker: %r: %r' % (name, e))
/home/kumarv/willa099/miniconda3/envs/pytorch4/lib/python3.6/site-packages/sklearn/externals/joblib/externals/loky/backend/semaphore_tracker.py:213: UserWarning: semaphore_tracker: '/loky-20360-_geccm6c': FileNotFoundError(2, 'No such file or directory')
  warnings.warn('semaphore_tracker: %r: %r' % (name, e))
/home/kumarv/willa099/miniconda3/envs/pytorch4/lib/python3.6/site-packages/sklearn/externals/joblib/externals/loky/backend/semaphore_tracker.py:213: UserWarning: semaphore_tracker: '/loky-20360-9m5tox6b': FileNotFoundError(2, 'No such file or directory')
  warnings.warn('semaphore_tracker: %r: %r' % (name, e))
/home/kumarv/willa099/miniconda3/envs/pytorch4/lib/python3.6/site-packages/sklearn/externals/joblib/externals/loky/backend/semaphore_tracker.py:213: UserWarning: semaphore_tracker: '/loky-20360-qe4s44q9': FileNotFoundError(2, 'No such file or directory')
  warnings.warn('semaphore_tracker: %r: %r' % (name, e))
/home/kumarv/willa099/miniconda3/envs/pytorch4/lib/python3.6/site-packages/sklearn/externals/joblib/externals/loky/backend/semaphore_tracker.py:213: UserWarning: semaphore_tracker: '/loky-20360-k5kd_b1b': FileNotFoundError(2, 'No such file or directory')
  warnings.warn('semaphore_tracker: %r: %r' % (name, e))
